<?xml version="1.0" ?>
<sdf version="1.6">
  <model name="jetank_robot">
    <static>false</static>
    <link name="main_chassis">
      <pose>0 0 0.055 0 0 0</pose>
      <inertial>
        <mass>10.0</mass>
        <inertia>
          <ixx>0.1</ixx>
          <iyy>0.1</iyy>
          <izz>0.1</izz>
        </inertia>
      </inertial>
      <collision name="chassis_collision">
        <geometry>
          <box>
            <size>0.2 0.1 0.08</size>
          </box>
        </geometry>
        <surface>
          <friction>
            <ode>
              <mu>0.5</mu>
              <mu2>0.5</mu2>
            </ode>
          </friction>
        </surface>
      </collision>
      <visual name="chassis_visual">
        <geometry>
          <box>
            <size>0.2 0.1 0.08</size>
          </box>
        </geometry>
        <material>
          <script>
            <uri>file://media/materials/scripts/gazebo.material</uri>
            <name>Gazebo/Blue</name>
          </script>
        </material>
      </visual>
    </link>

    <link name="left_wheel_front">
      <pose>0.06 0.0725 0.03 0 1.5707 1.5707</pose>
      <inertial>
        <mass>1.0</mass>
        <inertia>
          <ixx>0.01</ixx>
          <iyy>0.01</iyy>
          <izz>0.01</izz>
        </inertia>
      </inertial>
      <collision name="collision">
        <geometry>
          <cylinder>
            <radius>0.03</radius>
            <length>0.045</length>
          </cylinder>
        </geometry>
      </collision>
      <visual name="visual">
        <geometry>
          <cylinder>
            <radius>0.03</radius>
            <length>0.045</length>
          </cylinder>
        </geometry>
        <material>
          <script>
            <uri>file://media/materials/scripts/gazebo.material</uri>
            <name>Gazebo/Black</name>
          </script>
        </material>
      </visual>
    </link>
    <joint name="left_wheel_front_joint" type="revolute">
      <parent>main_chassis</parent>
      <child>left_wheel_front</child>
      <axis>
        <xyz>0 1 0</xyz>
        <limit>
          <lower>-1.0</lower>
          <upper>1.0</upper>
        </limit>
      </axis>
    </joint>
  </model>
</sdf>
